<?xml version="1.0" ?>
<!-- =================================================================================== -->
<!-- |    This document was autogenerated by xacro from iiwa.urdf.xacro                | -->
<!-- |    EDITING THIS FILE BY HAND IS NOT RECOMMENDED                                 | -->
<!-- =================================================================================== -->
<robot name="iiwa" xmlns:xacro="http://ros.org/wiki/xacro">
  <material name="Black">
    <color rgba="0.0 0.0 0.0 0.75"/>
  </material>
  <material name="Blue">
    <color rgba="0.0 0.0 0.8 1.0"/>
  </material>
  <material name="Green">
    <color rgba="0.0 0.8 0.0 1.0"/>
  </material>
  <material name="Grey">
    <color rgba="0.4 0.4 0.4 1.0"/>
  </material>
  <material name="Orange">
    <color rgba="1.0 0.423529411765 0.0392156862745 1.0"/>
  </material>
  <material name="Brown">
    <color rgba="0.870588235294 0.811764705882 0.764705882353 1.0"/>
  </material>
  <material name="Red">
    <color rgba="0.8 0.0 0.0 1.0"/>
  </material>
  <material name="White">
    <color rgba="1.0 1.0 1.0 0.75"/>
  </material>
  <!-- Fix to world just for testing -->
  <link name="world"/>
  <!--table-=======================================================================-->
  <link name="table_link">
    <inertial>
      <origin rpy="0 0 0" xyz="0 0 0"/>
      <mass value="1356.3"/>
      <inertia ixx="317.03" ixy="-4.2091E-15" ixz="-34.819" iyy="319.07" iyz="-1.0336E-14" izz="395.56"/>
    </inertial>
    <visual>
      <origin rpy="0 0 0" xyz="0 -0.650 0"/>
      <geometry>
        <mesh filename="package://iiwa_description/meshes/base_part0_table.stl"/>
      </geometry>
      <material name="White"/>
    </visual>
    <collision>
      <origin rpy="0 0 0" xyz="-0.2 -2.165 0"/>
      <geometry>
        <mesh filename="package://iiwa_description/meshes/base_part0_table_c.stl"/>
      </geometry>
      <material name="White"/>
    </collision>
  </link>
  <!--===========================================================================-->
  <!--lift-======================================================================-->
  <joint name="table_lift_joint" type="fixed">
    <origin rpy="0 0 0" xyz="0.526 0 0.913"/>
    <parent link="table_link"/>
    <child link="lift_link"/>
    <axis xyz="0 0 1"/>
    <limit effort="100" lower="0" upper="0.450" velocity="1.0"/>
    <dynamics damping="50" friction="1"/>
  </joint>
  <link name="lift_link">
    <inertial>
      <origin rpy="0 0 0" xyz="0.0060477 -2.2204E-16 0.019996"/>
      <mass value="47.592"/>
      <inertia ixx="2.0644" ixy="-3.1389E-16" ixz="0.023131" iyy="1.3888" iyz="-1.493E-16" izz="0.96152"/>
    </inertial>
    <visual>
      <origin rpy="0 0 0" xyz="-0.240 -0.260 0"/>
      <geometry>
        <mesh filename="package://iiwa_description/meshes/base_part1_lift.stl"/>
      </geometry>
      <material name="Brown"/>
    </visual>
    <collision>
      <origin rpy="0 0 0" xyz="-0.240 -0.260 0"/>
      <geometry>
        <mesh filename="package://iiwa_description/meshes/base_part1_lift.stl"/>
      </geometry>
      <material name="Brown"/>
    </collision>
  </link>
  <!-- <transmission name="lift_tran">
            <robotNamespace>/iiwa</robotNamespace>
            <type>transmission_interface/SimpleTransmission</type>
            <joint name="table_lift_joint">
                    <hardwareInterface>hardware_interface/PositionJointInterface</hardwareInterface>
            </joint>
            <actuator name="lift_motor">
                    <hardwareInterface>PositionJointInterface</hardwareInterface>
                    <mechanicalReduction>1</mechanicalReduction>
            </actuator>
        </transmission> -->
  <!--===========================================================================-->
  <!--neck-=======================================================================-->
  <joint name="lift_neck_joint" type="fixed">
    <origin rpy="0 0 0" xyz="-0.105 0 0.599"/>
    <parent link="lift_link"/>
    <child link="neck_link"/>
    <axis xyz="0 0 1"/>
    <limit effort="300" lower="-0.7854" upper="0.7854" velocity="1"/>
    <dynamics damping="50" friction="1"/>
  </joint>
  <link name="neck_link">
    <inertial>
      <origin rpy="0 0 0" xyz="-0.014292 -7.9519E-10 0.10385"/>
      <mass value="18.271"/>
      <inertia ixx="0.41379" ixy="7.3286E-10" ixz="0.00029645" iyy="0.11273" iyz="1.5388E-11" izz="0.34968"/>
    </inertial>
    <visual>
      <origin rpy="0 0 0" xyz="-0.075 -0.255 -0.005"/>
      <geometry>
        <mesh filename="package://iiwa_description/meshes/base_part2_neck.stl"/>
      </geometry>
      <material name="Red"/>
    </visual>
    <collision>
      <origin rpy="0 0 0" xyz="-0.075 -0.255 -0.005"/>
      <geometry>
        <mesh filename="package://iiwa_description/meshes/base_part2_neck.stl"/>
      </geometry>
      <material name="Red"/>
    </collision>
  </link>
  <!-- <transmission name="neck_tran">
            <robotNamespace>/iiwa</robotNamespace>
            <type>transmission_interface/SimpleTransmission</type>
            <joint name="lift_neck_joint">
                    <hardwareInterface>hardware_interface/PositionJointInterface</hardwareInterface>
            </joint>
            <actuator name="neck_motor">
                    <hardwareInterface>PositionJointInterface</hardwareInterface>
                    <mechanicalReduction>1</mechanicalReduction>
            </actuator>
        </transmission> -->
  <!--===========================================================================-->
  <!--camera_holder-===================================================================-->
  <joint name="camera_holder_joint" type="fixed">
    <origin rpy="0 0 0" xyz="0 0 0.220"/>
    <parent link="neck_link"/>
    <child link="camera_holder_link"/>
  </joint>
  <link name="camera_holder_link">
    <inertial>
      <origin rpy="0 0 0" xyz="0 0 0"/>
      <mass value="10"/>
      <inertia ixx="0.41379" ixy="7.3286E-10" ixz="0.00029645" iyy="0.11273" iyz="1.5388E-11" izz="0.34968"/>
    </inertial>
    <visual>
      <origin rpy="0 0 0" xyz="-0.590 -0.080 0"/>
      <geometry>
        <mesh filename="package://iiwa_description/meshes/base_part3_camera_holder.stl"/>
      </geometry>
      <material name="White"/>
    </visual>
    <collision>
      <origin rpy="0 0 0" xyz="-0.590 -0.080 0"/>
      <geometry>
        <mesh filename="package://iiwa_description/meshes/base_part3_camera_holder_c.stl"/>
      </geometry>
      <material name="White"/>
    </collision>
  </link>
  <!--===========================================================================-->
  <!--cushion-===================================================================-->
  <joint name="table_cushion_joint" type="fixed">
    <origin rpy="0 0 0" xyz="0.95 0 1.0"/>
    <parent link="table_link"/>
    <child link="cushion_link"/>
  </joint>
  <link name="cushion_link">
    <inertial>
      <origin rpy="0 0 0" xyz="0 0 0"/>
      <mass value="5"/>
      <inertia ixx="0.05" ixy="0" ixz="0" iyy="0.06" iyz="0" izz="0.03"/>
    </inertial>
    <visual>
      <origin rpy="0 0 0" xyz=" 0.2 0 0"/>
      <geometry>
        <box size="1.1 1.6 0.068"/>
      </geometry>
      <material name="Gold"/>
    </visual>
    <collision>
      <origin rpy="0 0 0" xyz="0.2 0 0"/>
      <geometry>
        <box size="1.1 1.6 0.068"/>
      </geometry>
      <material name="Gold"/>
    </collision>
  </link>
  <!--===========================================================================-->
  <!--reference frame-=============================================================-->
  <joint name="reference_frame_joint" type="fixed">
    <origin rpy="0 0 0" xyz="0 0 0.034"/>
    <parent link="cushion_link"/>
    <child link="reference_frame"/>
  </joint>
  <link name="reference_frame">
    <visual>
      <origin rpy="0 0 0" xyz="0 0 0"/>
      <geometry>
        <sphere radius="0.01"/>
      </geometry>
      <material name="Black"/>
    </visual>
  </link>
  <!--===========================================================================-->
  <!-- Table Link -->
  <gazebo reference="table_link">
    <material>Gazebo/Grey</material>
    <mu1>0.2</mu1>
    <mu2>0.2</mu2>
  </gazebo>
  <!-- Lift Link -->
  <gazebo reference="lift_link">
    <material>Gazebo/White</material>
    <mu1>0.2</mu1>
    <mu2>0.2</mu2>
  </gazebo>
  <!-- Neck Link -->
  <gazebo reference="neck_link">
    <material>Gazebo/Red</material>
    <mu1>0.2</mu1>
    <mu2>0.2</mu2>
  </gazebo>
  <!-- Cushion Link -->
  <gazebo reference="cushion_link">
    <material>Gazebo/Gold</material>
    <mu1>0.2</mu1>
    <mu2>0.2</mu2>
  </gazebo>
  <joint name="world_table_joint" type="fixed">
    <origin rpy="0 0 0" xyz="0 0 0"/>
    <parent link="world"/>
    <child link="table_link"/>
  </joint>
  <!-- neck_link -->
  <!--joint between {parent} and link_0-->
  <joint name="neck_link_R_joint" type="fixed">
    <origin rpy="0 1.57079632679 -0.436332312999" xyz="0.010 -0.158604 0.105"/>
    <parent link="neck_link"/>
    <child link="R_link_0"/>
  </joint>
  <link name="R_link_0">
    <inertial>
      <origin rpy="0 0 0" xyz="-0.1 0 0.07"/>
      <mass value="5"/>
      <inertia ixx="0.05" ixy="0" ixz="0" iyy="0.06" iyz="0" izz="0.03"/>
    </inertial>
    <visual>
      <origin rpy="0 0 0" xyz="0 0 0"/>
      <geometry>
        <mesh filename="package://iiwa_description/meshes/iiwa7/visual/link_0.stl"/>
      </geometry>
      <material name="Grey"/>
    </visual>
    <collision>
      <origin rpy="0 0 0" xyz="0 0 0"/>
      <geometry>
        <mesh filename="package://iiwa_description/meshes/iiwa7/collision/link_0.stl"/>
      </geometry>
      <material name="Grey"/>
    </collision>
    <self_collision_checking>
      <origin rpy="0 0 0" xyz="0 0 0"/>
      <geometry>
        <capsule length="0.25" radius="0.15"/>
      </geometry>
    </self_collision_checking>
  </link>
  <!-- joint between link_0 and link_1 -->
  <joint name="R_joint_1" type="revolute">
    <parent link="R_link_0"/>
    <child link="R_link_1"/>
    <origin rpy="0 0 0" xyz="0 0 0.15"/>
    <axis xyz="0 0 1"/>
    <limit effort="300" lower="-2.96705972839" upper="2.96705972839" velocity="10"/>
    <safety_controller k_position="100" k_velocity="2" soft_lower_limit="-2.93215314335" soft_upper_limit="2.93215314335"/>
    <dynamics damping="0.5"/>
  </joint>
  <link name="R_link_1">
    <inertial>
      <origin rpy="0 0 0" xyz="0 -0.03 0.12"/>
      <mass value="3.4525"/>
      <inertia ixx="0.02183" ixy="0" ixz="0" iyy="0.007703" iyz="-0.003887" izz="0.02083"/>
    </inertial>
    <visual>
      <origin rpy="0 0 0" xyz="0 0 0.0075"/>
      <geometry>
        <mesh filename="package://iiwa_description/meshes/iiwa7/visual/link_1.stl"/>
      </geometry>
      <material name="Orange"/>
    </visual>
    <collision>
      <origin rpy="0 0 0" xyz="0 0 0.0075"/>
      <geometry>
        <mesh filename="package://iiwa_description/meshes/iiwa7/collision/link_1.stl"/>
      </geometry>
      <material name="Orange"/>
    </collision>
  </link>
  <joint name="R_joint_2" type="revolute">
    <parent link="R_link_1"/>
    <child link="R_link_2"/>
    <origin rpy="1.57079632679   0 3.14159265359" xyz="0 0 0.19"/>
    <axis xyz="0 0 1"/>
    <limit effort="300" lower="-2.09439510239" upper="2.09439510239" velocity="10"/>
    <safety_controller k_position="100" k_velocity="2" soft_lower_limit="-2.05948851735" soft_upper_limit="2.05948851735"/>
    <dynamics damping="0.5"/>
  </joint>
  <link name="R_link_2">
    <inertial>
      <origin rpy="0 0 0" xyz="0.0003 0.059 0.042"/>
      <mass value="3.4821"/>
      <inertia ixx="0.02076" ixy="0" ixz="-0.003626" iyy="0.02179" iyz="0" izz="0.00779"/>
    </inertial>
    <visual>
      <origin rpy="0 0 0" xyz="0 0 0"/>
      <geometry>
        <mesh filename="package://iiwa_description/meshes/iiwa7/visual/link_2.stl"/>
      </geometry>
      <material name="Orange"/>
    </visual>
    <collision>
      <origin rpy="0 0 0" xyz="0 0 0"/>
      <geometry>
        <mesh filename="package://iiwa_description/meshes/iiwa7/collision/link_2.stl"/>
      </geometry>
      <material name="Orange"/>
    </collision>
  </link>
  <joint name="R_joint_3" type="revolute">
    <parent link="R_link_2"/>
    <child link="R_link_3"/>
    <origin rpy="1.57079632679 0 3.14159265359" xyz="0 0.21 0"/>
    <axis xyz="0 0 1"/>
    <limit effort="300" lower="-2.96705972839" upper="2.96705972839" velocity="10"/>
    <safety_controller k_position="100" k_velocity="2" soft_lower_limit="-2.93215314335" soft_upper_limit="2.93215314335"/>
    <dynamics damping="0.5"/>
  </joint>
  <link name="R_link_3">
    <inertial>
      <origin rpy="0 0 0" xyz="0 0.03 0.13"/>
      <mass value="4.05623"/>
      <inertia ixx="0.03204" ixy="0" ixz="0" iyy="0.00972" iyz="0.006227" izz="0.03042"/>
    </inertial>
    <visual>
      <origin rpy="0 0 0" xyz="0 0 -0.026"/>
      <geometry>
        <mesh filename="package://iiwa_description/meshes/iiwa7/visual/link_3.stl"/>
      </geometry>
      <material name="Orange"/>
    </visual>
    <collision>
      <origin rpy="0 0 0" xyz="0 0 -0.026"/>
      <geometry>
        <mesh filename="package://iiwa_description/meshes/iiwa7/collision/link_3.stl"/>
      </geometry>
      <material name="Orange"/>
    </collision>
  </link>
  <joint name="R_joint_4" type="revolute">
    <parent link="R_link_3"/>
    <child link="R_link_4"/>
    <origin rpy="1.57079632679 0 0" xyz="0 0 0.19"/>
    <axis xyz="0 0 1"/>
    <limit effort="300" lower="-2.09439510239" upper="2.09439510239" velocity="10"/>
    <safety_controller k_position="100" k_velocity="2" soft_lower_limit="-2.05948851735" soft_upper_limit="2.05948851735"/>
    <dynamics damping="0.5"/>
  </joint>
  <link name="R_link_4">
    <inertial>
      <origin rpy="0 0 0" xyz="0 0.067 0.034"/>
      <mass value="3.4822"/>
      <inertia ixx="0.02178" ixy="0" ixz="0" iyy="0.02075" iyz="-0.003625" izz="0.007785"/>
    </inertial>
    <visual>
      <origin rpy="0 0 0" xyz="0 0 0"/>
      <geometry>
        <mesh filename="package://iiwa_description/meshes/iiwa7/visual/link_4.stl"/>
      </geometry>
      <material name="Orange"/>
    </visual>
    <collision>
      <origin rpy="0 0 0" xyz="0 0 0"/>
      <geometry>
        <mesh filename="package://iiwa_description/meshes/iiwa7/collision/link_4.stl"/>
      </geometry>
      <material name="Orange"/>
    </collision>
  </link>
  <joint name="R_joint_5" type="revolute">
    <parent link="R_link_4"/>
    <child link="R_link_5"/>
    <origin rpy="-1.57079632679 3.14159265359 0" xyz="0 0.21 0"/>
    <axis xyz="0 0 1"/>
    <limit effort="300" lower="-2.96705972839" upper="2.96705972839" velocity="10"/>
    <safety_controller k_position="100" k_velocity="2" soft_lower_limit="-2.93215314335" soft_upper_limit="2.93215314335"/>
    <dynamics damping="0.5"/>
  </joint>
  <link name="R_link_5">
    <inertial>
      <origin rpy="0 0 0" xyz="0.0001 0.021 0.076"/>
      <mass value="2.1633"/>
      <inertia ixx="0.01287" ixy="0" ixz="0" iyy="0.005708" iyz="-0.003946" izz="0.01112"/>
    </inertial>
    <visual>
      <origin rpy="0 0 0" xyz="0 0 -0.026"/>
      <geometry>
        <mesh filename="package://iiwa_description/meshes/iiwa7/visual/link_5.stl"/>
      </geometry>
      <material name="Orange"/>
    </visual>
    <collision>
      <origin rpy="0 0 0" xyz="0 0 -0.026"/>
      <geometry>
        <mesh filename="package://iiwa_description/meshes/iiwa7/collision/link_5.stl"/>
      </geometry>
      <material name="Orange"/>
    </collision>
  </link>
  <joint name="R_joint_6" type="revolute">
    <parent link="R_link_5"/>
    <child link="R_link_6"/>
    <origin rpy="1.57079632679 0 0" xyz="0 0.06070 0.19"/>
    <axis xyz="0 0 1"/>
    <limit effort="300" lower="-2.09439510239" upper="2.09439510239" velocity="10"/>
    <safety_controller k_position="100" k_velocity="2" soft_lower_limit="-2.05948851735" soft_upper_limit="2.05948851735"/>
    <dynamics damping="0.5"/>
  </joint>
  <link name="R_link_6">
    <inertial>
      <origin rpy="0 0 0" xyz="0 0.0006 0.0004"/>
      <mass value="2.3466"/>
      <inertia ixx="0.006509" ixy="0" ixz="0" iyy="0.006259" iyz="0.00031891" izz="0.004527"/>
    </inertial>
    <visual>
      <origin rpy="0 0 0" xyz="0 0 0"/>
      <geometry>
        <mesh filename="package://iiwa_description/meshes/iiwa7/visual/link_6.stl"/>
      </geometry>
      <material name="Orange"/>
    </visual>
    <collision>
      <origin rpy="0 0 0" xyz="0 0 0"/>
      <geometry>
        <mesh filename="package://iiwa_description/meshes/iiwa7/collision/link_6.stl"/>
      </geometry>
      <material name="Orange"/>
    </collision>
  </link>
  <joint name="R_joint_7" type="revolute">
    <parent link="R_link_6"/>
    <child link="R_link_7"/>
    <origin rpy="-1.57079632679 3.14159265359 0" xyz="0 0.081 0.06070"/>
    <axis xyz="0 0 1"/>
    <limit effort="300" lower="-3.05432619099" upper="3.05432619099" velocity="10"/>
    <safety_controller k_position="100" k_velocity="2" soft_lower_limit="-3.01941960595" soft_upper_limit="3.01941960595"/>
    <dynamics damping="0.5"/>
  </joint>
  <link name="R_link_7">
    <inertial>
      <origin rpy="0 0 0" xyz="0 0 0.02"/>
      <mass value="3.129"/>
      <inertia ixx="0.01464" ixy="0.0005912" ixz="0" iyy="0.01465" iyz="0" izz="0.002872"/>
    </inertial>
    <visual>
      <origin rpy="0 0 0" xyz="0 0 -0.0005"/>
      <geometry>
        <mesh filename="package://iiwa_description/meshes/iiwa7/visual/link_7.stl"/>
      </geometry>
      <material name="Grey"/>
    </visual>
    <collision>
      <origin rpy="0 0 0" xyz="0 0 -0.0005"/>
      <geometry>
        <mesh filename="package://iiwa_description/meshes/iiwa7/collision/link_7.stl"/>
      </geometry>
      <material name="Grey"/>
    </collision>
  </link>
  <joint name="R_joint_ee" type="fixed">
    <parent link="R_link_7"/>
    <child link="R_link_ee"/>
    <origin rpy="0 0 0" xyz="0 0 0.295"/>
  </joint>
  <link name="R_link_ee"> </link>
  <!-- Load Gazebo lib and set the robot namespace -->
  <!--<gazebo>
      <plugin name="gazebo_ros_control" filename="libgazebo_ros_control.so">
        <robotNamespace>/iiwa</robotNamespace>
        <robotSimType>gazebo_ros_control/DefaultRobotHWSim</robotSimType>
        <legacyModeNS>true</legacyModeNS>
      </plugin>
    </gazebo>-->
  <!-- Link0 -->
  <gazebo reference="R_link_0">
    <material>Gazebo/Grey</material>
    <mu1>0.2</mu1>
    <mu2>0.2</mu2>
  </gazebo>
  <!-- Link1 -->
  <gazebo reference="R_link_1">
    <material>Gazebo/Orange</material>
    <mu1>0.2</mu1>
    <mu2>0.2</mu2>
  </gazebo>
  <!-- Link2 -->
  <gazebo reference="R_link_2">
    <material>Gazebo/Orange</material>
    <mu1>0.2</mu1>
    <mu2>0.2</mu2>
  </gazebo>
  <!-- Link3 -->
  <gazebo reference="R_link_3">
    <material>Gazebo/Orange</material>
    <mu1>0.2</mu1>
    <mu2>0.2</mu2>
  </gazebo>
  <!-- Link4 -->
  <gazebo reference="R_link_4">
    <material>Gazebo/Orange</material>
    <mu1>0.2</mu1>
    <mu2>0.2</mu2>
  </gazebo>
  <!-- Link5 -->
  <gazebo reference="R_link_5">
    <material>Gazebo/Orange</material>
    <mu1>0.2</mu1>
    <mu2>0.2</mu2>
  </gazebo>
  <!-- Link6 -->
  <gazebo reference="R_link_6">
    <material>Gazebo/Orange</material>
    <mu1>0.2</mu1>
    <mu2>0.2</mu2>
  </gazebo>
  <!-- Link7 -->
  <gazebo reference="R_link_7">
    <material>Gazebo/Grey</material>
    <mu1>0.2</mu1>
    <mu2>0.2</mu2>
  </gazebo>
  <transmission name="R_tran_1">
    <robotNamespace>/iiwa</robotNamespace>
    <type>transmission_interface/SimpleTransmission</type>
    <joint name="R_joint_1">
      <hardwareInterface>hardware_interface/PositionJointInterface</hardwareInterface>
    </joint>
    <actuator name="R_motor_1">
      <hardwareInterface>PositionJointInterface</hardwareInterface>
      <mechanicalReduction>1</mechanicalReduction>
    </actuator>
  </transmission>
  <transmission name="R_tran_2">
    <robotNamespace>/iiwa</robotNamespace>
    <type>transmission_interface/SimpleTransmission</type>
    <joint name="R_joint_2">
      <hardwareInterface>hardware_interface/PositionJointInterface</hardwareInterface>
    </joint>
    <actuator name="R_motor_2">
      <hardwareInterface>PositionJointInterface</hardwareInterface>
      <mechanicalReduction>1</mechanicalReduction>
    </actuator>
  </transmission>
  <transmission name="R_tran_3">
    <robotNamespace>/iiwa</robotNamespace>
    <type>transmission_interface/SimpleTransmission</type>
    <joint name="R_joint_3">
      <hardwareInterface>hardware_interface/PositionJointInterface</hardwareInterface>
    </joint>
    <actuator name="R_motor_3">
      <hardwareInterface>PositionJointInterface</hardwareInterface>
      <mechanicalReduction>1</mechanicalReduction>
    </actuator>
  </transmission>
  <transmission name="R_tran_4">
    <robotNamespace>/iiwa</robotNamespace>
    <type>transmission_interface/SimpleTransmission</type>
    <joint name="R_joint_4">
      <hardwareInterface>hardware_interface/PositionJointInterface</hardwareInterface>
    </joint>
    <actuator name="R_motor_4">
      <hardwareInterface>PositionJointInterface</hardwareInterface>
      <mechanicalReduction>1</mechanicalReduction>
    </actuator>
  </transmission>
  <transmission name="R_tran_5">
    <robotNamespace>/iiwa</robotNamespace>
    <type>transmission_interface/SimpleTransmission</type>
    <joint name="R_joint_5">
      <hardwareInterface>hardware_interface/PositionJointInterface</hardwareInterface>
    </joint>
    <actuator name="R_motor_5">
      <hardwareInterface>PositionJointInterface</hardwareInterface>
      <mechanicalReduction>1</mechanicalReduction>
    </actuator>
  </transmission>
  <transmission name="R_tran_6">
    <robotNamespace>/iiwa</robotNamespace>
    <type>transmission_interface/SimpleTransmission</type>
    <joint name="R_joint_6">
      <hardwareInterface>hardware_interface/PositionJointInterface</hardwareInterface>
    </joint>
    <actuator name="R_motor_6">
      <hardwareInterface>PositionJointInterface</hardwareInterface>
      <mechanicalReduction>1</mechanicalReduction>
    </actuator>
  </transmission>
  <transmission name="R_tran_7">
    <robotNamespace>/iiwa</robotNamespace>
    <type>transmission_interface/SimpleTransmission</type>
    <joint name="R_joint_7">
      <hardwareInterface>hardware_interface/PositionJointInterface</hardwareInterface>
    </joint>
    <actuator name="R_motor_7">
      <hardwareInterface>PositionJointInterface</hardwareInterface>
      <mechanicalReduction>1</mechanicalReduction>
    </actuator>
  </transmission>
  <!--===========================================================================-->
  <!--Left Robotiq gripper==-0.160-======================================================-->
  <!--<xacro:robotiq_arg2f_140 prefix="L_"/>
  <joint name="L_gripper_joint" type="fixed">
      <origin xyz="0 0 ${0.011-0.225}" rpy="0 0 ${PI/2}"/>
      <parent link="L_link_ee"/>
      <child link="L_robotiq_arg2f_base_link"/>
  </joint>-->
  <link name="R_robotiq_arg2f_base_link">
    <inertial>
      <origin rpy="0 0 0" xyz="8.625E-08 -4.6583E-06 0.03145"/>
      <mass value="0.22652"/>
      <inertia ixx="0.00020005" ixy="-4.2442E-10" ixz="-2.9069E-10" iyy="0.00017832" iyz="-3.4402E-08" izz="0.00013478"/>
    </inertial>
    <visual>
      <origin rpy="0 0 0" xyz="0 0 0"/>
      <geometry>
        <mesh filename="package://robotiq_2f_140_gripper_visualization/meshes/visual/robotiq_arg2f_base_link.stl"/>
      </geometry>
      <material name="">
        <color rgba="0.1 0.1 0.1 1"/>
      </material>
    </visual>
    <collision>
      <origin rpy="0 0 0" xyz="0 0 0"/>
      <geometry>
        <mesh filename="package://robotiq_2f_140_gripper_visualization/meshes/collision/robotiq_arg2f_base_link.stl"/>
      </geometry>
    </collision>
  </link>
  <link name="R_left_outer_knuckle">
    <inertial>
      <origin rpy="0 0 0" xyz="-0.000200000000003065 0.0199435877845359 0.0292245259211331"/>
      <mass value="0.00853198276973456"/>
      <inertia ixx="2.89328108496468E-06" ixy="-1.57935047237397E-19" ixz="-1.93980378593255E-19" iyy="1.86719750325683E-06" iyz="-1.21858577871576E-06" izz="1.21905238907251E-06"/>
    </inertial>
    <visual>
      <origin rpy="0 0 0" xyz="0 0 0"/>
      <geometry>
        <mesh filename="package://robotiq_2f_140_gripper_visualization/meshes/visual/robotiq_arg2f_140_outer_knuckle.stl"/>
      </geometry>
      <material name="">
        <color rgba="0.792156862745098 0.819607843137255 0.933333333333333 1"/>
      </material>
    </visual>
    <collision>
      <origin rpy="0 0 0" xyz="0 0 0"/>
      <geometry>
        <mesh filename="package://robotiq_2f_140_gripper_visualization/meshes/collision/robotiq_arg2f_140_outer_knuckle.stl"/>
      </geometry>
    </collision>
  </link>
  <link name="R_left_outer_finger">
    <inertial>
      <origin rpy="0 0 0" xyz="0.00030115855001899 0.0373907951953854 -0.0208027427000385"/>
      <mass value="0.022614240507152"/>
      <inertia ixx="1.52518312458174E-05" ixy="9.76583423954399E-10" ixz="-5.43838577022588E-10" iyy="6.17694243867776E-06" iyz="6.78636130740228E-06" izz="1.16494917907219E-05"/>
    </inertial>
    <visual>
      <origin rpy="0 0 0" xyz="0 0 0"/>
      <geometry>
        <mesh filename="package://robotiq_2f_140_gripper_visualization/meshes/visual/robotiq_arg2f_140_outer_finger.stl"/>
      </geometry>
      <material name="">
        <color rgba="0.1 0.1 0.1 1"/>
      </material>
    </visual>
    <collision>
      <origin rpy="0 0 0" xyz="0 0 0"/>
      <geometry>
        <mesh filename="package://robotiq_2f_140_gripper_visualization/meshes/collision/robotiq_arg2f_140_outer_finger.stl"/>
      </geometry>
    </collision>
  </link>
  <link name="R_left_inner_finger">
    <inertial>
      <origin rpy="0 0 0" xyz="0.000299999999999317 0.0160078233491243 -0.0136945669206257"/>
      <mass value="0.0104003125914103"/>
      <inertia ixx="2.71909453810972E-06" ixy="1.35402465472579E-21" ixz="-7.1817349065269E-22" iyy="7.69100314106116E-07" iyz="6.74715432769696E-07" izz="2.30315190420171E-06"/>
    </inertial>
    <visual>
      <origin rpy="0 0 0" xyz="0 0 0"/>
      <geometry>
        <mesh filename="package://robotiq_2f_140_gripper_visualization/meshes/visual/robotiq_arg2f_140_inner_finger.stl"/>
      </geometry>
      <material name="">
        <color rgba="0.1 0.1 0.1 1"/>
      </material>
    </visual>
    <collision>
      <origin rpy="0 0 0" xyz="0 0 0"/>
      <geometry>
        <mesh filename="package://robotiq_2f_140_gripper_visualization/meshes/collision/robotiq_arg2f_140_inner_finger.stl"/>
      </geometry>
    </collision>
  </link>
  <link name="R_left_inner_finger_pad">
    <visual>
      <origin rpy="0 0 0" xyz="0 0 0"/>
      <geometry>
        <box size="0.027 0.065 0.0075"/>
      </geometry>
      <material name="">
        <color rgba="0.9 0.9 0.9 1"/>
      </material>
    </visual>
    <collision>
      <origin rpy="0 0 0" xyz="0 0 0"/>
      <geometry>
        <box size="0.03 0.07 0.0075"/>
      </geometry>
      <material name="">
        <color rgba="0.9 0.0 0.0 1"/>
      </material>
    </collision>
  </link>
  <link name="R_left_inner_knuckle">
    <inertial>
      <origin rpy="0 0 0" xyz="0.000123011831763771 0.0507850843201817 0.00103968640075166"/>
      <mass value="0.0271177346495152"/>
      <inertia ixx="2.61910379223783E-05" ixy="-2.43616858946494E-07" ixz="-6.37789906117123E-09" iyy="2.8270243746167E-06" iyz="-5.37200748039765E-07" izz="2.83695868220296E-05"/>
    </inertial>
    <visual>
      <origin rpy="0 0 0" xyz="0 0 0"/>
      <geometry>
        <mesh filename="package://robotiq_2f_140_gripper_visualization/meshes/visual/robotiq_arg2f_140_inner_knuckle.stl"/>
      </geometry>
      <material name="">
        <color rgba="0.1 0.1 0.1 1"/>
      </material>
    </visual>
    <collision>
      <origin rpy="0 0 0" xyz="0 0 0"/>
      <geometry>
        <mesh filename="package://robotiq_2f_140_gripper_visualization/meshes/collision/robotiq_arg2f_140_inner_knuckle.stl"/>
      </geometry>
    </collision>
  </link>
  <link name="R_right_outer_knuckle">
    <inertial>
      <origin rpy="0 0 0" xyz="-0.000200000000003065 0.0199435877845359 0.0292245259211331"/>
      <mass value="0.00853198276973456"/>
      <inertia ixx="2.89328108496468E-06" ixy="-1.57935047237397E-19" ixz="-1.93980378593255E-19" iyy="1.86719750325683E-06" iyz="-1.21858577871576E-06" izz="1.21905238907251E-06"/>
    </inertial>
    <visual>
      <origin rpy="0 0 0" xyz="0 0 0"/>
      <geometry>
        <mesh filename="package://robotiq_2f_140_gripper_visualization/meshes/visual/robotiq_arg2f_140_outer_knuckle.stl"/>
      </geometry>
      <material name="">
        <color rgba="0.792156862745098 0.819607843137255 0.933333333333333 1"/>
      </material>
    </visual>
    <collision>
      <origin rpy="0 0 0" xyz="0 0 0"/>
      <geometry>
        <mesh filename="package://robotiq_2f_140_gripper_visualization/meshes/collision/robotiq_arg2f_140_outer_knuckle.stl"/>
      </geometry>
    </collision>
  </link>
  <link name="R_right_outer_finger">
    <inertial>
      <origin rpy="0 0 0" xyz="0.00030115855001899 0.0373907951953854 -0.0208027427000385"/>
      <mass value="0.022614240507152"/>
      <inertia ixx="1.52518312458174E-05" ixy="9.76583423954399E-10" ixz="-5.43838577022588E-10" iyy="6.17694243867776E-06" iyz="6.78636130740228E-06" izz="1.16494917907219E-05"/>
    </inertial>
    <visual>
      <origin rpy="0 0 0" xyz="0 0 0"/>
      <geometry>
        <mesh filename="package://robotiq_2f_140_gripper_visualization/meshes/visual/robotiq_arg2f_140_outer_finger.stl"/>
      </geometry>
      <material name="">
        <color rgba="0.1 0.1 0.1 1"/>
      </material>
    </visual>
    <collision>
      <origin rpy="0 0 0" xyz="0 0 0"/>
      <geometry>
        <mesh filename="package://robotiq_2f_140_gripper_visualization/meshes/collision/robotiq_arg2f_140_outer_finger.stl"/>
      </geometry>
    </collision>
  </link>
  <link name="R_right_inner_finger">
    <inertial>
      <origin rpy="0 0 0" xyz="0.000299999999999317 0.0160078233491243 -0.0136945669206257"/>
      <mass value="0.0104003125914103"/>
      <inertia ixx="2.71909453810972E-06" ixy="1.35402465472579E-21" ixz="-7.1817349065269E-22" iyy="7.69100314106116E-07" iyz="6.74715432769696E-07" izz="2.30315190420171E-06"/>
    </inertial>
    <visual>
      <origin rpy="0 0 0" xyz="0 0 0"/>
      <geometry>
        <mesh filename="package://robotiq_2f_140_gripper_visualization/meshes/visual/robotiq_arg2f_140_inner_finger.stl"/>
      </geometry>
      <material name="">
        <color rgba="0.1 0.1 0.1 1"/>
      </material>
    </visual>
    <collision>
      <origin rpy="0 0 0" xyz="0 0 0"/>
      <geometry>
        <mesh filename="package://robotiq_2f_140_gripper_visualization/meshes/collision/robotiq_arg2f_140_inner_finger.stl"/>
      </geometry>
    </collision>
  </link>
  <link name="R_right_inner_finger_pad">
    <visual>
      <origin rpy="0 0 0" xyz="0 0 0"/>
      <geometry>
        <box size="0.027 0.065 0.0075"/>
      </geometry>
      <material name="">
        <color rgba="0.9 0.9 0.9 1"/>
      </material>
    </visual>
    <collision>
      <origin rpy="0 0 0" xyz="0 0 0"/>
      <geometry>
        <box size="0.03 0.07 0.0075"/>
      </geometry>
      <material name="">
        <color rgba="0.9 0.0 0.0 1"/>
      </material>
    </collision>
  </link>
  <link name="R_right_inner_knuckle">
    <inertial>
      <origin rpy="0 0 0" xyz="0.000123011831763771 0.0507850843201817 0.00103968640075166"/>
      <mass value="0.0271177346495152"/>
      <inertia ixx="2.61910379223783E-05" ixy="-2.43616858946494E-07" ixz="-6.37789906117123E-09" iyy="2.8270243746167E-06" iyz="-5.37200748039765E-07" izz="2.83695868220296E-05"/>
    </inertial>
    <visual>
      <origin rpy="0 0 0" xyz="0 0 0"/>
      <geometry>
        <mesh filename="package://robotiq_2f_140_gripper_visualization/meshes/visual/robotiq_arg2f_140_inner_knuckle.stl"/>
      </geometry>
      <material name="">
        <color rgba="0.1 0.1 0.1 1"/>
      </material>
    </visual>
    <collision>
      <origin rpy="0 0 0" xyz="0 0 0"/>
      <geometry>
        <mesh filename="package://robotiq_2f_140_gripper_visualization/meshes/collision/robotiq_arg2f_140_inner_knuckle.stl"/>
      </geometry>
    </collision>
  </link>
  <joint name="R_finger_joint" type="revolute">
    <origin rpy="2.29579632679 0 0" xyz="0 -0.030601 0.054905"/>
    <parent link="R_robotiq_arg2f_base_link"/>
    <child link="R_left_outer_knuckle"/>
    <axis xyz="-1 0 0"/>
    <limit effort="1000" lower="0" upper="0.7" velocity="2.0"/>
  </joint>
  <joint name="R_left_outer_finger_joint" type="fixed">
    <origin rpy="0 0 0" xyz="0 0.01821998610742 0.0260018192872234"/>
    <parent link="R_left_outer_knuckle"/>
    <child link="R_left_outer_finger"/>
    <axis xyz="1 0 0"/>
  </joint>
  <joint name="R_left_inner_knuckle_joint" type="revolute">
    <origin rpy="2.29579632679 0 0.0" xyz="0 -0.0127 0.06142"/>
    <parent link="R_robotiq_arg2f_base_link"/>
    <child link="R_left_inner_knuckle"/>
    <axis xyz="1 0 0"/>
    <limit effort="1000" lower="-0.8757" upper="0.8757" velocity="2.0"/>
    <mimic joint="R_finger_joint" multiplier="-1" offset="0"/>
  </joint>
  <joint name="R_left_inner_finger_joint" type="revolute">
    <origin rpy="-0.725 0 0" xyz="0 0.0817554015893473 -0.0282203446692936"/>
    <parent link="R_left_outer_finger"/>
    <child link="R_left_inner_finger"/>
    <axis xyz="1 0 0"/>
    <limit effort="1000" lower="-0.8757" upper="0.8757" velocity="2.0"/>
    <mimic joint="R_finger_joint" multiplier="1" offset="0"/>
  </joint>
  <joint name="R_left_inner_finger_pad_joint" type="fixed">
    <origin rpy="0 0 0" xyz="0 0.0457554015893473 -0.0272203446692936"/>
    <parent link="R_left_inner_finger"/>
    <child link="R_left_inner_finger_pad"/>
    <axis xyz="0 0 1"/>
  </joint>
  <joint name="R_right_outer_knuckle_joint" type="revolute">
    <origin rpy="2.29579632679 0 3.14159265359" xyz="0 0.030601 0.054905"/>
    <parent link="R_robotiq_arg2f_base_link"/>
    <child link="R_right_outer_knuckle"/>
    <axis xyz="1 0 0"/>
    <limit effort="1000" lower="-0.725" upper="0.725" velocity="2.0"/>
    <mimic joint="R_finger_joint" multiplier="-1" offset="0"/>
  </joint>
  <joint name="R_right_outer_finger_joint" type="fixed">
    <origin rpy="0 0 0" xyz="0 0.01821998610742 0.0260018192872234"/>
    <parent link="R_right_outer_knuckle"/>
    <child link="R_right_outer_finger"/>
    <axis xyz="1 0 0"/>
  </joint>
  <joint name="R_right_inner_knuckle_joint" type="revolute">
    <origin rpy="2.29579632679 0 -3.14159265359" xyz="0 0.0127 0.06142"/>
    <parent link="R_robotiq_arg2f_base_link"/>
    <child link="R_right_inner_knuckle"/>
    <axis xyz="1 0 0"/>
    <limit effort="1000" lower="-0.8757" upper="0.8757" velocity="2.0"/>
    <mimic joint="R_finger_joint" multiplier="-1" offset="0"/>
  </joint>
  <joint name="R_right_inner_finger_joint" type="revolute">
    <origin rpy="-0.725 0 0" xyz="0 0.0817554015893473 -0.0282203446692936"/>
    <parent link="R_right_outer_finger"/>
    <child link="R_right_inner_finger"/>
    <axis xyz="1 0 0"/>
    <limit effort="1000" lower="-0.8757" upper="0.8757" velocity="2.0"/>
    <mimic joint="R_finger_joint" multiplier="1" offset="0"/>
  </joint>
  <joint name="R_right_inner_finger_pad_joint" type="fixed">
    <origin rpy="0 0 0" xyz="0 0.0457554015893473 -0.0272203446692936"/>
    <parent link="R_right_inner_finger"/>
    <child link="R_right_inner_finger_pad"/>
    <axis xyz="0 0 1"/>
  </joint>
  <transmission name="R_finger_joint_trans">
    <type>transmission_interface/SimpleTransmission</type>
    <joint name="R_finger_joint">
      <hardwareInterface>hardware_interface/PositionJointInterface</hardwareInterface>
    </joint>
    <actuator name="R_finger_joint_motor">
      <mechanicalReduction>1</mechanicalReduction>
      <hardwareInterface>hardware_interface/PositionJointInterface</hardwareInterface>
    </actuator>
  </transmission>
  <gazebo>
    <plugin filename="libroboticsgroup_gazebo_mimic_joint_plugin.so" name="R_mimic_robotiq_140_1">
      <joint>R_finger_joint</joint>
      <mimicJoint>R_right_outer_knuckle_joint</mimicJoint>
      <multiplier>-1.0</multiplier>
      <offset>0.0</offset>
    </plugin>
    <plugin filename="libroboticsgroup_gazebo_mimic_joint_plugin.so" name="R_mimic_robotiq_140_2">
      <joint>R_finger_joint</joint>
      <mimicJoint>R_left_inner_knuckle_joint</mimicJoint>
      <multiplier>-1.0</multiplier>
      <offset>0.0</offset>
    </plugin>
    <plugin filename="libroboticsgroup_gazebo_mimic_joint_plugin.so" name="R_mimic_robotiq_140_3">
      <joint>R_finger_joint</joint>
      <mimicJoint>R_right_inner_knuckle_joint</mimicJoint>
      <multiplier>-1.0</multiplier>
      <offset>0.0</offset>
    </plugin>
    <plugin filename="libroboticsgroup_gazebo_mimic_joint_plugin.so" name="R_mimic_robotiq_140_4">
      <joint>R_finger_joint</joint>
      <mimicJoint>R_left_inner_finger_joint</mimicJoint>
      <multiplier>1.0</multiplier>
      <offset>0.0</offset>
    </plugin>
    <plugin filename="libroboticsgroup_gazebo_mimic_joint_plugin.so" name="R_mimic_robotiq_140_5">
      <joint>R_finger_joint</joint>
      <mimicJoint>R_right_inner_finger_joint</mimicJoint>
      <multiplier>1.0</multiplier>
      <offset>0.0</offset>
    </plugin>
  </gazebo>
  <gazebo reference="R_robotiq_arg2f_base_link">
    <material>Gazebo/Black</material>
    <implicitSpringDamper>1</implicitSpringDamper>
    <mu1>100000</mu1>
    <mu2>100000</mu2>
    <kp>100000000.0</kp>
    <kd>1.0</kd>
  </gazebo>
  <gazebo reference="R_left_outer_knuckle">
    <material>Gazebo/White</material>
    <implicitSpringDamper>1</implicitSpringDamper>
    <mu1>100000</mu1>
    <mu2>100000</mu2>
    <kp>100000000.0</kp>
    <kd>1.0</kd>
  </gazebo>
  <gazebo reference="R_right_outer_knuckle">
    <material>Gazebo/White</material>
    <implicitSpringDamper>1</implicitSpringDamper>
    <mu1>100000</mu1>
    <mu2>100000</mu2>
    <kp>100000000.0</kp>
    <kd>1.0</kd>
  </gazebo>
  <gazebo reference="R_left_outer_finger">
    <material>Gazebo/Black</material>
    <implicitSpringDamper>1</implicitSpringDamper>
    <mu1>100000</mu1>
    <mu2>100000</mu2>
    <kp>100000000.0</kp>
    <kd>1.0</kd>
  </gazebo>
  <gazebo reference="R_right_outer_finger">
    <material>Gazebo/Black</material>
    <implicitSpringDamper>1</implicitSpringDamper>
    <mu1>100000</mu1>
    <mu2>100000</mu2>
    <kp>100000000.0</kp>
    <kd>1.0</kd>
  </gazebo>
  <gazebo reference="R_left_inner_knuckle">
    <material>Gazebo/Black</material>
    <implicitSpringDamper>1</implicitSpringDamper>
    <mu1>100000</mu1>
    <mu2>100000</mu2>
    <kp>100000000.0</kp>
    <kd>1.0</kd>
  </gazebo>
  <gazebo reference="R_right_inner_knuckle">
    <material>Gazebo/Black</material>
    <implicitSpringDamper>1</implicitSpringDamper>
    <mu1>100000</mu1>
    <mu2>100000</mu2>
    <kp>100000000.0</kp>
    <kd>1.0</kd>
  </gazebo>
  <gazebo reference="R_left_inner_finger">
    <material>Gazebo/White</material>
    <implicitSpringDamper>1</implicitSpringDamper>
    <mu1>100000</mu1>
    <mu2>100000</mu2>
    <kp>100000000.0</kp>
    <kd>1.0</kd>
  </gazebo>
  <gazebo reference="R_right_inner_finger">
    <material>Gazebo/White</material>
    <implicitSpringDamper>1</implicitSpringDamper>
    <mu1>100000</mu1>
    <mu2>100000</mu2>
    <kp>100000000.0</kp>
    <kd>1.0</kd>
  </gazebo>
  <gazebo reference="R_left_inner_finger_pad">
    <implicitSpringDamper>1</implicitSpringDamper>
    <mu1>100000</mu1>
    <mu2>100000</mu2>
    <kp>100000000.0</kp>
    <kd>1.0</kd>
  </gazebo>
  <gazebo reference="R_right_inner_finger_pad">
    <implicitSpringDamper>1</implicitSpringDamper>
    <mu1>100000</mu1>
    <mu2>100000</mu2>
    <kp>100000000.0</kp>
    <kd>1.0</kd>
  </gazebo>
  <!--<gazebo>
            <plugin name="gazebo_grasp_fix" filename="libgazebo_grasp_fix.so">
                <arm>
                    <arm_name>${prefix}iiwa_arm</arm_name>
                    <palm_link>${prefix}link_7</palm_link>
                    <gripper_link>${prefix}left_inner_finger</gripper_link>
                    <gripper_link>${prefix}right_inner_finger</gripper_link>
                </arm>
                <forces_angle_tolerance>100</forces_angle_tolerance>
                <update_rate>2</update_rate>
                <grip_count_threshold>1</grip_count_threshold>
                <max_grip_count>2</max_grip_count>
                <release_tolerance>0.005</release_tolerance>
                <disable_collisions_on_attach>true</disable_collisions_on_attach>
                <contact_topic>__default_topic__</contact_topic>
            </plugin>
	    </gazebo>-->
  <joint name="R_gripper_joint" type="fixed">
    <origin rpy="0 0 1.57079632679" xyz="0 0 -0.214"/>
    <parent link="R_link_ee"/>
    <child link="R_robotiq_arg2f_base_link"/>
  </joint>
  <!--=========================================================================-->
  <!-- Load Gazebo lib and set the robot namespace -->
  <gazebo>
    <plugin filename="libgazebo_ros_control.so" name="gazebo_ros_control">
      <robotNamespace>/iiwa</robotNamespace>
      <robotSimType>gazebo_ros_control/DefaultRobotHWSim</robotSimType>
      <legacyModeNS>true</legacyModeNS>
    </plugin>
  </gazebo>
</robot>
